Workbook
Name FOOT_BRAND: Rules!$I$49:$I$51
Name NO_NAME_CN: Rules!$I$54:$I$56
Name SITE_GLASS: Rules!$I$54:$I$56

Sheet External Prices
A2: Price in EUR, EXW workshop | B2: Country | AG2: Factors | AH2: Pump + LC | AI2: Tank
A3: Overruling agreements | B3: Walk away | AG3: Overruling | AH3: =IF($B$3<>"None",VLOOKUP($B$3,Rules!$P$6:$X$57,9,FALSE),0) -> 0.001 | AI3: =IF($B$3<>"None",VLOOKUP($B$3,Rules!$Z$6:$AH$57,9,FALSE),0) -> 0.001
A4: Country | B4: United Kingdom | AG4: Country | AH4: =IF($AH$3<>0%,0,VLOOKUP($B$4, Rules!$A$6:$D$201, 4, FALSE)) -> 0 | AI4: =IF($AH$3<>0%,0,VLOOKUP($B$4, Rules!$A$6:$D$201, 4, FALSE)) -> 0
A5: Agent fee | B5: No | C5: =AH5 -> 0 | AG5: Agent | AH5: =IF($AH$3<>0%,0,IF($B$5 <> "Yes",0, VLOOKUP($B$4, Rules!$A$6:$D$201, 3,FALSE))) -> 0 | AI5: =IF($AH$3<>0%,0,IF($B$5 <> "Yes",0, VLOOKUP($B$4, Rules!$A$6:$D$201, 3,FALSE))) -> 0
A6: Negotiation fee | B6: Yes | C6: =AH6 -> 0 | AG6: Negotiation | AH6: =IF($AH$3<>0%,0,IF($B$6 <> "Yes",0, VLOOKUP($B$4, Rules!$A$6:$D$201, 2,FALSE))) -> 0 | AI6: =IF($AH$3<>0%,0,IF($B$6 <> "Yes",0, VLOOKUP($B$4, Rules!$A$6:$D$201, 2,FALSE))) -> 0
A7: Order "when" | B7: 2025 | AG7: Order "when" | AH7: =IF($AH$3<>0%,0,VLOOKUP($B$7, Rules!$F$6:$G$7, 2, FALSE)) -> 0 | AI7: =IF($AH$3<>0%,0,VLOOKUP($B$7, Rules!$F$6:$G$7, 2, FALSE)) -> 0
A8: Competetion | B8: Standard | AG8: Competetion | AH8: =IF($AH$3<>0%,0,VLOOKUP($B$8, Rules!$M$6:$N$7, 2,FALSE)) -> 0 | AI8: =IF($AH$3<>0%,0,VLOOKUP($B$8, Rules!$M$6:$N$7, 2,FALSE)) -> 0
A9: Client | B9: Any w. Agent | AG9: Client | AH9: =IF($AH$3<>0%,0,VLOOKUP($B$9, Rules!$I$6:$J$10, 2,FALSE)) -> 0 | AI9: =IF($AH$3<>0%,0,VLOOKUP($B$9, Rules!$I$6:$J$10, 2,FALSE)) -> 0
A10: Design level | B10: Standard | AG10: Design level | AH10: =IF($AH$3<>0%,0,VLOOKUP($B$10, Rules!$K$6:$L$7, 2,FALSE)) -> 0 | AI10: =IF($AH$3<>0%,0,VLOOKUP($B$10, Rules!$K$6:$L$7, 2,FALSE)) -> 0
AG12: Total | AH12: =(1/(1-AH3)/(1-AH4)/(1-AH7)/(1-AH5)/(1-AH6)/(1-AH9)/(1-AH10)/(1-AH8)) -> 1.001001 | AI12: =(1/(1-AI3)/(1-AI4)/(1-AI7)/(1-AI5)/(1-AI6)/(1-AI9)/(1-AI10)/(1-AI8)) -> 1.001001
A14: Technical adjustment | B14: Power | E14: 22 kW | F14: 22 kW | G14: 22 kW | H14: 22 kW | I14: 11 kW | J14: 11 kW | K14: 22 kW | L14: 22 kW | N14: 22 kW | O14: 22 kW | P14: 22 kW | Q14: 22 kW | R14: 22 kW | S14: 22 kW | T14: 22 kW | U14: 22 kW | V14: 22 kW | W14: 22 kW | X14: 30 kW | Y14: 55 kW | Z14: 22 kW | AA14: 22 kW | AB14: 55 kW | AC14: =B14 -> Power
B15: Extra powder inlets | P15: 0 | W15: 0 | X15: 2 | Y15: 0 | Z15: 2 | AA15: 2 | AB15: 0 | AC15: =B15 -> Extra powder inlets
B16: V50 TinkTop | H16: No | N16: Yes | O16: No | P16: No | R16: No | S16: No | T16: No | U16: No | V16: No | W16: No | X16: Yes | Y16: No | Z16: No | AA16: Yes | AB16: No | AC16: =B16 -> V50 TinkTop
B17: Vacuum pump | P17: 5.5 MS | W17: 5.5 SS | X17: 5.5 SS | Y17: 5.5 SS | Z17: 4.0 SS | AA17: 5.5 SS | AB17: 5.5 SS | AC17: =B17 -> Vacuum pump
B18: Foot brand | I18: MARTIN | J18: MARTIN | K18: MARTIN | L18: NGI | M18: MARTIN | N18: NGI | O18: MARTIN | P18: NGI | R18: MARTIN | S18: MARTIN | T18: MARTIN | U18: NGI | V18: NGI | W18: NGI | X18: NGI | Y18: NGI | Z18: MARTIN | AA18: NGI | AB18: NGI | AC18: =B18 -> Foot brand
B19: Site glass brand | P19: EBORA EU | R19: NONE | S19: NONE | T19: NONE | U19: EBORA EU | V19: EBORA EU | W19: EBORA EU | X19: EBORA EU | Y19: EBORA EU | Z19: EBORA EU | AA19: EBORA EU | AB19: EBORA EU | AC19: =B19 -> Site glass brand
B20: CIP opiton | P20: Yes | R20: No | S20: No | T20: No | U20: Yes | V20: Yes | W20: Yes | X20: Yes | Y20: Yes | Z20: Yes | AA20: Yes | AB20: Yes | AC20: =B20 -> CIP opiton
B21: Non-foam | P21: Yes | R21: No | S21: No | T21: No | U21: Yes | V21: Yes | W21: Yes | X21: Yes | Y21: Yes | Z21: Yes | AA21: Yes | AB21: Yes | AC21: =B21 -> Non-foam
B22: Tangential inlet | P22: Yes | R22: No | S22: No | T22: No | U22: No | V22: No | W22: Yes | X22: Yes | Y22: Yes | Z22: No | AA22: Yes | AB22: Yes | AC22: =B22 -> Tangential inlet
B23: Minor ingredients tank connection (MBV) | P23: Yes | W23: Yes | X23: Yes | Y23: Yes | Z23: Yes | AA23: Yes | AB23: Yes | AC23: =B23 -> Minor ingredients tank connection (MBV)
B24: 300 mm impeller system | P24: No | T24: No | X24: No | Y24: No | AA24: No | AB24: No | AC24: =B24 -> 300 mm impeller system
B25: Insulation & Cladding | P25: No | R25: No | S25: No | T25: No | U25: No | V25: No | W25: No | X25: Yes | Y25: No | Z25: No | AA25: No | AB25: No | AC25: =B25 -> Insulation & Cladding
B26: Jacket, Insulation & Cladding | P26: No | R26: No | S26: No | T26: No | U26: No | V26: No | W26: No | X26: No | Y26: No | Z26: Yes | AA26: Yes | AB26: Yes | AC26: =B26 -> Jacket, Insulation & Cladding
B27: Coaxial system | Z27: No | AA27: No | AB27: No | AC27: =B27 -> Coaxial system
B28: Double high-shear unit | S28: No | T28: No | Y28: Yes | Z28: No | AA28: No | AB28: Yes | AC28: =B28 -> Double high-shear unit
B29: Steam Injection nozzles | Z29: No | AA29: No | AB29: No | AC29: =B29 -> Steam Injection nozzles
B30: Culinary steam unit, 5 µm | Z30: No | AA30: No | AB30: No | AC30: =B30 -> Culinary steam unit, 5 µm
B31: 22L tank CIP | P31: No | W31: No | X31: No | Y31: No | Z31: No | AA31: No | AB31: No | AC31: =B31 -> 22L tank CIP | AD31: AL Manway, CIP spray ball, Acutator, IFM safety
B32: EU Documentation | I32: No | J32: No | K32: No | L32: No | M32: No | N32: No | O32: No | P32: No | Q32: Yes | R32: No | S32: No | T32: No | U32: No | V32: No | W32: No | X32: Yes | Y32: No | Z32: No | AA32: Yes | AB32: No | AC32: =B32 -> EU Documentation
B33: Polish & Grind external welds | P33: No | R33: No | S33: No | T33: No | U33: No | V33: No | W33: No | X33: No | Y33: No | Z33: Yes | AA33: No | AB33: No | AC33: =B33 -> Polish & Grind external welds
B34: Tangential Inlet hose | P34: No | R34: No | S34: No | T34: No | U34: No | V34: No | W34: No | X34: No | Y34: No | Z34: No | AA34: No | AB34: No | AC34: =B34 -> Tangential Inlet hose
B35: Outlet hose | P35: No | R35: No | S35: No | T35: No | U35: No | V35: No | W35: No | X35: No | Y35: No | Z35: No | AA35: No | AB35: No | AC35: =B35 -> Outlet hose
B36: Ingredients inlet hoses | P36: No | W36: No | X36: Yes | Y36: No | Z36: No | AA36: Yes | AB36: No | AC36: =B36 -> Ingredients inlet hoses
B38: Workshop | E38: DK | F38: DK | G38: DK | H38: DK | I38: VN | J38: VN | K38: VN | L38: VN | M38: VN | N38: VN | O38: VN | P38: VN | R38: VN | S38: VN | T38: VN | U38: VN | V38: VN | W38: VN | X38: VN | Y38: VN | Z38: VN | AA38: VN | AB38: VN
B39: Equipment | D39: Options | E39: Shear | F39: Shear L | G39: Injector | H39: Vortex | I39: Injector site assemble | J39: Shear | K39: Loop | L39: Injector | M39: Vortex site assemble | N39: Vortex | O39: Vortex VN 800 | P39: Vortex Vacuum 2000 | Q39: Bottom Shear | R39: LC 500 | S39: LC 1000 | T39: LC3000 | U39: Standard 500 | V39: Standard 1000 | W39: Vacuum 500 | X39: Vacuum 1000 | Y39: Vacuum 3000 | Z39: Process 500 | AA39: Process 1000 | AB39: Process 3000
B40: Price w/o options below | E40: =ROUNDUP('Internal Sales price'!E218*'External Prices'!$AH$12,0) -> 15593 | F40: =ROUNDUP('Internal Sales price'!F218*'External Prices'!$AH$12,0) -> 17480 | G40: =ROUNDUP('Internal Sales price'!H218*'External Prices'!$AH$12,0) -> 21743 | H40: =ROUNDUP('Internal Sales price'!J218*'External Prices'!$AH$12,0) -> 30134 | I40: =ROUNDUP('Internal Sales price'!L218*'External Prices'!$AH$12,0) -> 12413 | J40: =ROUNDUP('Internal Sales price'!N218*'External Prices'!$AH$12,0) -> 20058 | K40: =ROUNDUP('Internal Sales price'!P218*'External Prices'!$AH$12,0) -> 21869 | L40: =ROUNDUP('Internal Sales price'!R218*'External Prices'!$AH$12,0) -> 25050 | N40: =ROUNDUP('Internal Sales price'!V218*'External Prices'!$AH$12,0) -> 29811 | O40: =ROUNDUP('Internal Sales price'!X218*'External Prices'!$AH$12,0) -> 52357 | P40: =ROUNDUP('Internal Sales price'!Z218*'External Prices'!$AI$12,0) -> 104435 | Q40: =ROUNDUP('Internal Sales price'!AB218*'External Prices'!$AI$12,0) -> 15447 | R40: =ROUNDUP('Internal Sales price'!AD218*'External Prices'!$AH$12,0) -> 36809 | S40: =ROUNDUP('Internal Sales price'!AE218*'External Prices'!$AH$12,0) -> 37818 | T40: =ROUNDUP('Internal Sales price'!AF218*'External Prices'!$AH$12,0) -> 49680 | U40: =ROUNDUP('Internal Sales price'!AH218*'External Prices'!$AI$12,0) -> 56083 | V40: =ROUNDUP('Internal Sales price'!AI218*'External Prices'!$AI$12,0) -> 57191 | W40: =ROUNDUP('Internal Sales price'!AK218*'External Prices'!$AI$12,0) -> 95206 | X40: =ROUNDUP('Internal Sales price'!AL218*'External Prices'!$AI$12,0) -> 117464 | Y40: =ROUNDUP('Internal Sales price'!AM218*'External Prices'!$AI$12,0) -> 130198 | Z40: =ROUNDUP('Internal Sales price'!AO218*'External Prices'!$AI$12,0) -> 120644 | AA40: =ROUNDUP('Internal Sales price'!AP218*'External Prices'!$AI$12,0) -> 148861 | AB40: =ROUNDUP('Internal Sales price'!AQ218*'External Prices'!$AI$12,0) -> 170773
B41: Control Panel & VSD, 11 kW | D41: ='Internal Sales price'!$AS$218*'External Prices'!$AH$12 -> 5606.6659 | E41: ='Internal Sales price'!$AS$218*'External Prices'!$AH$12 -> 5606.6659 | F41: ='Internal Sales price'!$AS$218*'External Prices'!$AH$12 -> 5606.6659 | G41: ='Internal Sales price'!$AS$218*'External Prices'!$AH$12 -> 5606.6659 | H41: ='Internal Sales price'!$AS$218*'External Prices'!$AH$12 -> 5606.6659 | I41: ='Internal Sales price'!$AS$218*'External Prices'!$AH$12 -> 5606.6659 | J41: ='Internal Sales price'!$AS$218*'External Prices'!$AH$12 -> 5606.6659 | K41: ='Internal Sales price'!$AS$218*'External Prices'!$AH$12 -> 5606.6659 | L41: ='Internal Sales price'!$AS$218*'External Prices'!$AH$12 -> 5606.6659 | N41: ='Internal Sales price'!$AS$218*'External Prices'!$AH$12 -> 5606.6659 | O41: ='Internal Sales price'!$AS$218*'External Prices'!$AH$12 -> 5606.6659
B42: Control Panel & VSD, 15 kW | D42: ='Internal Sales price'!$AT$218*'External Prices'!$AH$12 -> 5766.122 | E42: ='Internal Sales price'!$AT$218*'External Prices'!$AH$12 -> 5766.122 | F42: ='Internal Sales price'!$AT$218*'External Prices'!$AH$12 -> 5766.122 | G42: ='Internal Sales price'!$AT$218*'External Prices'!$AH$12 -> 5766.122 | H42: ='Internal Sales price'!$AT$218*'External Prices'!$AH$12 -> 5766.122 | I42: ='Internal Sales price'!$AT$218*'External Prices'!$AH$12 -> 5766.122 | J42: ='Internal Sales price'!$AT$218*'External Prices'!$AH$12 -> 5766.122 | K42: ='Internal Sales price'!$AT$218*'External Prices'!$AH$12 -> 5766.122 | L42: ='Internal Sales price'!$AT$218*'External Prices'!$AH$12 -> 5766.122 | N42: ='Internal Sales price'!$AT$218*'External Prices'!$AH$12 -> 5766.122 | O42: ='Internal Sales price'!$AT$218*'External Prices'!$AH$12 -> 5766.122
B43: Control Panel & VSD, 18.5 kW | D43: ='Internal Sales price'!$AU$218*'External Prices'!$AH$12 -> 5925.5781 | E43: ='Internal Sales price'!$AU$218*'External Prices'!$AH$12 -> 5925.5781 | F43: ='Internal Sales price'!$AU$218*'External Prices'!$AH$12 -> 5925.5781 | G43: ='Internal Sales price'!$AU$218*'External Prices'!$AH$12 -> 5925.5781 | H43: ='Internal Sales price'!$AU$218*'External Prices'!$AH$12 -> 5925.5781 | I43: ='Internal Sales price'!$AU$218*'External Prices'!$AH$12 -> 5925.5781 | J43: ='Internal Sales price'!$AU$218*'External Prices'!$AH$12 -> 5925.5781 | K43: ='Internal Sales price'!$AU$218*'External Prices'!$AH$12 -> 5925.5781 | L43: ='Internal Sales price'!$AU$218*'External Prices'!$AH$12 -> 5925.5781 | N43: ='Internal Sales price'!$AU$218*'External Prices'!$AH$12 -> 5925.5781 | O43: ='Internal Sales price'!$AU$218*'External Prices'!$AH$12 -> 5925.5781
B44: Control Panel & VSD, 22 kW | D44: ='Internal Sales price'!$AV$218*'External Prices'!$AH$12 -> 6786.5913 | E44: ='Internal Sales price'!$AV$218*'External Prices'!$AH$12 -> 6786.5913 | F44: ='Internal Sales price'!$AV$218*'External Prices'!$AH$12 -> 6786.5913 | G44: ='Internal Sales price'!$AV$218*'External Prices'!$AH$12 -> 6786.5913 | H44: ='Internal Sales price'!$AV$218*'External Prices'!$AH$12 -> 6786.5913 | I44: ='Internal Sales price'!$AV$218*'External Prices'!$AH$12 -> 6786.5913 | J44: ='Internal Sales price'!$AV$218*'External Prices'!$AH$12 -> 6786.5913 | K44: ='Internal Sales price'!$AV$218*'External Prices'!$AH$12 -> 6786.5913 | L44: ='Internal Sales price'!$AV$218*'External Prices'!$AH$12 -> 6786.5913 | N44: ='Internal Sales price'!$AV$218*'External Prices'!$AH$12 -> 6786.5913 | O44: ='Internal Sales price'!$AV$218*'External Prices'!$AH$12 -> 6786.5913
...

Sheet Internal Sales price
E1: Shear | F1: Shear L | H1: Injector | J1: Vortex | L1: Injector site assemble | N1: Shear VN | P1: Loop VN | R1: Injector VN | T1: Vortex site assemble | V1: Vortex VN | X1: Vortex VN 800 | Z1: Vortex Vacuum 2000 | AB1: Bottom Shear | AD1: LC 500 | AE1: LC 1000 | AF1: LC 3000 | AH1: Standard 500 | AI1: Standard 1000 | AK1: Vacuum 500 | AL1: Vacuum 1000 | AM1: Vacuum 3000 | AO1: Process 500 | AP1: Process 1000 | AQ1: Process 3000 | AS1: Control Panel & VSD, 11 kW | AT1: Control Panel & VSD, 15 kW | AU1: Control Panel & VSD, 18.5 kW | AV1: Control Panel & VSD, 22 kW | AW1: Control Panel & VSD, 30 kW | AX1: Frequency Converter 11 kW | AY1: Frequency Converter 15 kW | AZ1: Frequency Converter 18.5 kW | BA1: Frequency Converter 22 kW | BB1: MixSing Standard control 22 kW | BC1: MixSing Vacuum control 22 kW | BD1: MixSing Process control 22 kW | BE1: Table | BG1: Mesh | BH1: Seal flush | BI1: Connection to Client | BJ1: Packaging | BK1: Suction lance | BL1: Injector VN - TABLE ASSEMBLY
BC2: MIAC
E3: DK | F3: DK | H3: DK | J3: DK | L3: VN | N3: VN | R3: VN | T3: VN | V3: VN | X3: VN | Z3: VN | AB3: DK | AD3: VN | AE3: VN | AF3: VN | AH3: VN | AI3: VN | AK3: VN | AL3: VN | AM3: VN | AO3: VN | AP3: VN | AQ3: VN | AS3: VN | AT3: VN | AU3: VN | AV3: VN | AW3: VN | AX3: DK | AY3: DK | AZ3: DK | BA3: DK | BE3: DK | BG3: DK | BH3: DK
A4: TPS essiential package
B5: xx Mixer, diameter | E5: 160mm | F5: 160mm | Z5: 160mm | AB5: 160mm | AD5: 160mm | AE5: 160mm | AF5: 300mm | AK5: 160mm | AL5: 160mm | AM5: 300mm | AO5: 160mm | AP5: 160mm | AQ5: 300mm
B6: Motor consol | E6: =VLOOKUP($B6,'Cost prices'!$B$6:$H$538,7, FALSE) -> 5081 | F6: =VLOOKUP($B6,'Cost prices'!$B$6:$H$538,7, FALSE) -> 5081 | H6: =VLOOKUP($B6,'Cost prices'!$B$6:$H$538,7, FALSE) -> 5081 | J6: =VLOOKUP($B6,'Cost prices'!$B$6:$H$538,7, FALSE) -> 5081 | L6: =VLOOKUP($B6,'Cost prices'!$B$6:$H$538,7, FALSE) -> 5081 | N6: =VLOOKUP($B6,'Cost prices'!$B$6:$H$538,7, FALSE) -> 5081 | P6: =VLOOKUP($B6,'Cost prices'!$B$6:$H$538,7, FALSE) -> 5081 | R6: =VLOOKUP($B6,'Cost prices'!$B$6:$H$538,7, FALSE) -> 5081 | T6: =VLOOKUP($B6,'Cost prices'!$B$6:$H$538,7, FALSE) -> 5081 | V6: =VLOOKUP($B6,'Cost prices'!$B$6:$H$538,7, FALSE) -> 5081 | X6: =VLOOKUP($B6,'Cost prices'!$B$6:$H$538,7, FALSE) -> 5081 | Z6: =IF('External Prices'!P$24="No",VLOOKUP($B6,'Cost prices'!$B$6:$H$538,7,FALSE),VLOOKUP($B6,'Cost prices'!$B$6:$H$538,7,FALSE)*2) -> 5081 | AB6: =VLOOKUP($B6,'Cost prices'!$B$6:$H$538,7, FALSE) -> 5081 | AD6: =VLOOKUP($B6,'Cost prices'!$B$6:$H$538,7, FALSE) -> 5081 | AE6: =VLOOKUP($B6,'Cost prices'!$B$6:$H$538,7, FALSE)* IF('External Prices'!S$28<>"No",2,1) -> 5081 | AF6: =IF('External Prices'!T$24="No",VLOOKUP($B6,'Cost prices'!$B$6:$H$538,7,FALSE),VLOOKUP($B6,'Cost prices'!$B$6:$H$538,7,FALSE)*2)* IF('External Prices'!T$28<>"No",2,1) -> 5081 | AH6: =VLOOKUP($B6,'Cost prices'!$B$6:$H$538,7, FALSE) -> 5081 | AI6: =VLOOKUP($B6,'Cost prices'!$B$6:$H$538,7, FALSE) -> 5081 | AK6: =VLOOKUP($B6,'Cost prices'!$B$6:$H$538,7, FALSE) -> 5081 | AL6: =IF('External Prices'!X$24="No",VLOOKUP($B6,'Cost prices'!$B$6:$H$538,7,FALSE),VLOOKUP($B6,'Cost prices'!$B$6:$H$538,7,FALSE)*2) -> 5081 | AM6: =IF('External Prices'!Y$24="No",VLOOKUP($B6,'Cost prices'!$B$6:$H$538,7,FALSE),VLOOKUP($B6,'Cost prices'!$B$6:$H$538,7,FALSE)*2)* IF('External Prices'!Y$28<>"No",2,1) -> 10162 | AO6: =VLOOKUP($B6,'Cost prices'!$B$6:$H$538,7, FALSE)* IF('External Prices'!Z$28<>"No",2,1) -> 5081 | AP6: =IF('External Prices'!AA$24="No",VLOOKUP($B6,'Cost prices'!$B$6:$H$538,7,FALSE),VLOOKUP($B6,'Cost prices'!$B$6:$H$538,7,FALSE)*2)* IF('External Prices'!AA$28<>"No",2,1) -> 5081 | AQ6: =IF('External Prices'!AB$24="No",VLOOKUP($B6,'Cost prices'!$B$6:$H$538,7,FALSE),VLOOKUP($B6,'Cost prices'!$B$6:$H$538,7,FALSE)*2)* IF('External Prices'!AB$28<>"No",2,1) -> 10162
B7: Stator | E7: =VLOOKUP($B7,'Cost prices'!$B$6:$H$538,7, FALSE) -> 4720 | F7: =VLOOKUP($B7,'Cost prices'!$B$6:$H$538,7, FALSE) -> 4720 | H7: =VLOOKUP($B7,'Cost prices'!$B$6:$H$538,7, FALSE) -> 4720 | J7: =VLOOKUP($B7,'Cost prices'!$B$6:$H$538,7, FALSE) -> 4720 | L7: =VLOOKUP($B7,'Cost prices'!$B$6:$H$538,7, FALSE) -> 4720 | N7: =VLOOKUP($B7,'Cost prices'!$B$6:$H$538,7, FALSE) -> 4720 | P7: =VLOOKUP($B7,'Cost prices'!$B$6:$H$538,7, FALSE) -> 4720 | R7: =VLOOKUP($B7,'Cost prices'!$B$6:$H$538,7, FALSE) -> 4720 | T7: =VLOOKUP($B7,'Cost prices'!$B$6:$H$538,7, FALSE) -> 4720 | V7: =VLOOKUP($B7,'Cost prices'!$B$6:$H$538,7, FALSE) -> 4720 | X7: =VLOOKUP($B7,'Cost prices'!$B$6:$H$538,7, FALSE) -> 4720 | Z7: =IF('External Prices'!P$24="No",VLOOKUP($B7,'Cost prices'!$B$6:$H$538,7,FALSE),VLOOKUP($B7,'Cost prices'!$B$6:$H$538,7,FALSE)*1.5) -> 4720 | AB7: =VLOOKUP($B7,'Cost prices'!$B$6:$H$538,7, FALSE) -> 4720 | AD7: =VLOOKUP($B7,'Cost prices'!$B$6:$H$538,7, FALSE) -> 4720 | AE7: =VLOOKUP($B7,'Cost prices'!$B$6:$H$538,7, FALSE)* IF('External Prices'!S$28<>"No",2,1) -> 4720 | AF7: =IF('External Prices'!T$24="No",VLOOKUP($B7,'Cost prices'!$B$6:$H$538,7,FALSE),VLOOKUP($B7,'Cost prices'!$B$6:$H$538,7,FALSE)*1.5)* IF('External Prices'!T$28<>"No",2,1) -> 4720 | AH7: =VLOOKUP($B7,'Cost prices'!$B$6:$H$538,7, FALSE) -> 4720 | AI7: =VLOOKUP($B7,'Cost prices'!$B$6:$H$538,7, FALSE) -> 4720 | AK7: =VLOOKUP($B7,'Cost prices'!$B$6:$H$538,7, FALSE) -> 4720 | AL7: =IF('External Prices'!X$24="No",VLOOKUP($B7,'Cost prices'!$B$6:$H$538,7,FALSE),VLOOKUP($B7,'Cost prices'!$B$6:$H$538,7,FALSE)*1.5) -> 4720 | AM7: =IF('External Prices'!Y$24="No",VLOOKUP($B7,'Cost prices'!$B$6:$H$538,7,FALSE),VLOOKUP($B7,'Cost prices'!$B$6:$H$538,7,FALSE)*1.5)* IF('External Prices'!Y$28<>"No",2,1) -> 9440 | AO7: =VLOOKUP($B7,'Cost prices'!$B$6:$H$538,7, FALSE)* IF('External Prices'!Z$28<>"No",2,1) -> 4720 | AP7: =IF('External Prices'!AA$24="No",VLOOKUP($B7,'Cost prices'!$B$6:$H$538,7,FALSE),VLOOKUP($B7,'Cost prices'!$B$6:$H$538,7,FALSE)*1.5)* IF('External Prices'!AA$28<>"No",2,1) -> 4720 | AQ7: =IF('External Prices'!AB$24="No",VLOOKUP($B7,'Cost prices'!$B$6:$H$538,7,FALSE),VLOOKUP($B7,'Cost prices'!$B$6:$H$538,7,FALSE)*1.5)* IF('External Prices'!AB$28<>"No",2,1) -> 9440
B8: Impeller | E8: =VLOOKUP($B8,'Cost prices'!$B$6:$H$538,7, FALSE) -> 4307 | F8: =VLOOKUP($B8,'Cost prices'!$B$6:$H$538,7, FALSE) -> 4307 | H8: =VLOOKUP($B8,'Cost prices'!$B$6:$H$538,7, FALSE) -> 4307 | J8: =VLOOKUP($B8,'Cost prices'!$B$6:$H$538,7, FALSE) -> 4307 | L8: =VLOOKUP($B8,'Cost prices'!$B$6:$H$538,7, FALSE) -> 4307 | N8: =VLOOKUP($B8,'Cost prices'!$B$6:$H$538,7, FALSE) -> 4307 | P8: =VLOOKUP($B8,'Cost prices'!$B$6:$H$538,7, FALSE) -> 4307 | R8: =VLOOKUP($B8,'Cost prices'!$B$6:$H$538,7, FALSE) -> 4307 | T8: =VLOOKUP($B8,'Cost prices'!$B$6:$H$538,7, FALSE) -> 4307 | V8: =VLOOKUP($B8,'Cost prices'!$B$6:$H$538,7, FALSE) -> 4307 | X8: =VLOOKUP($B8,'Cost prices'!$B$6:$H$538,7, FALSE) -> 4307 | Z8: =IF('External Prices'!P$24="No",VLOOKUP($B8,'Cost prices'!$B$6:$H$538,7,FALSE),VLOOKUP($B8,'Cost prices'!$B$6:$H$538,7,FALSE)*1.5) -> 4307 | AB8: =VLOOKUP($B8,'Cost prices'!$B$6:$H$538,7, FALSE) -> 4307 | AD8: =VLOOKUP($B8,'Cost prices'!$B$6:$H$538,7, FALSE) -> 4307 | AE8: =VLOOKUP($B8,'Cost prices'!$B$6:$H$538,7, FALSE)* IF('External Prices'!S$28<>"No",2,1) -> 4307 | AF8: =IF('External Prices'!T$24="No",VLOOKUP($B8,'Cost prices'!$B$6:$H$538,7,FALSE),VLOOKUP($B8,'Cost prices'!$B$6:$H$538,7,FALSE)*1.5)* IF('External Prices'!T$28<>"No",2,1) -> 4307 | AH8: =VLOOKUP($B8,'Cost prices'!$B$6:$H$538,7, FALSE) -> 4307 | AI8: =VLOOKUP($B8,'Cost prices'!$B$6:$H$538,7, FALSE) -> 4307 | AK8: =VLOOKUP($B8,'Cost prices'!$B$6:$H$538,7, FALSE) -> 4307 | AL8: =IF('External Prices'!X$24="No",VLOOKUP($B8,'Cost prices'!$B$6:$H$538,7,FALSE),VLOOKUP($B8,'Cost prices'!$B$6:$H$538,7,FALSE)*1.5) -> 4307 | AM8: =IF('External Prices'!Y$24="No",VLOOKUP($B8,'Cost prices'!$B$6:$H$538,7,FALSE),VLOOKUP($B8,'Cost prices'!$B$6:$H$538,7,FALSE)*1.5)* IF('External Prices'!Y$28<>"No",2,1) -> 8614 | AO8: =VLOOKUP($B8,'Cost prices'!$B$6:$H$538,7, FALSE)* IF('External Prices'!Z$28<>"No",2,1) -> 4307 | AP8: =IF('External Prices'!AA$24="No",VLOOKUP($B8,'Cost prices'!$B$6:$H$538,7,FALSE),VLOOKUP($B8,'Cost prices'!$B$6:$H$538,7,FALSE)*1.5)* IF('External Prices'!AA$28<>"No",2,1) -> 4307 | AQ8: =IF('External Prices'!AB$24="No",VLOOKUP($B8,'Cost prices'!$B$6:$H$538,7,FALSE),VLOOKUP($B8,'Cost prices'!$B$6:$H$538,7,FALSE)*1.5)* IF('External Prices'!AB$28<>"No",2,1) -> 8614
B9: Pump house | E9: =VLOOKUP($B9,'Cost prices'!$B$6:$H$538,7, FALSE) -> 8591 | F9: =VLOOKUP($B9,'Cost prices'!$B$6:$H$538,7, FALSE) -> 8591 | H9: =VLOOKUP($B9,'Cost prices'!$B$6:$H$538,7, FALSE) -> 8591 | J9: =VLOOKUP($B9,'Cost prices'!$B$6:$H$538,7, FALSE) -> 8591 | L9: =VLOOKUP($B9,'Cost prices'!$B$6:$H$538,7, FALSE) -> 8591 | N9: =VLOOKUP($B9,'Cost prices'!$B$6:$H$538,7, FALSE) -> 8591 | P9: =VLOOKUP($B9,'Cost prices'!$B$6:$H$538,7, FALSE) -> 8591 | R9: =VLOOKUP($B9,'Cost prices'!$B$6:$H$538,7, FALSE) -> 8591 | T9: =VLOOKUP($B9,'Cost prices'!$B$6:$H$538,7, FALSE) -> 8591 | V9: =VLOOKUP($B9,'Cost prices'!$B$6:$H$538,7, FALSE) -> 8591 | X9: =VLOOKUP($B9,'Cost prices'!$B$6:$H$538,7, FALSE) -> 8591
A10: Not used | B10: Bottom
B11: Shaft seal | E11: =VLOOKUP($B11,'Cost prices'!$B$6:$H$538,7, FALSE) -> 1005 | F11: =VLOOKUP($B11,'Cost prices'!$B$6:$H$538,7, FALSE) -> 1005 | H11: =VLOOKUP($B11,'Cost prices'!$B$6:$H$538,7, FALSE) -> 1005 | J11: =VLOOKUP($B11,'Cost prices'!$B$6:$H$538,7, FALSE) -> 1005 | L11: =VLOOKUP($B11,'Cost prices'!$B$6:$H$538,7, FALSE) -> 1005 | N11: =VLOOKUP($B11,'Cost prices'!$B$6:$H$538,7, FALSE) -> 1005 | P11: =VLOOKUP($B11,'Cost prices'!$B$6:$H$538,7, FALSE) -> 1005 | R11: =VLOOKUP($B11,'Cost prices'!$B$6:$H$538,7, FALSE) -> 1005 | T11: =VLOOKUP($B11,'Cost prices'!$B$6:$H$538,7, FALSE) -> 1005 | V11: =VLOOKUP($B11,'Cost prices'!$B$6:$H$538,7, FALSE) -> 1005 | X11: =VLOOKUP($B11,'Cost prices'!$B$6:$H$538,7, FALSE) -> 1005 | Z11: =VLOOKUP($B11,'Cost prices'!$B$6:$H$538,7, FALSE) -> 1005 | AB11: =VLOOKUP($B11,'Cost prices'!$B$6:$H$538,7, FALSE) -> 1005 | AD11: =VLOOKUP($B11,'Cost prices'!$B$6:$H$538,7, FALSE) -> 1005 | AE11: =VLOOKUP($B11,'Cost prices'!$B$6:$H$538,7, FALSE)* IF('External Prices'!S$28<>"No",2,1) -> 1005 | AF11: =VLOOKUP($B11,'Cost prices'!$B$6:$H$538,7, FALSE)* IF('External Prices'!T$28<>"No",2,1) -> 1005 | AH11: =VLOOKUP($B11,'Cost prices'!$B$6:$H$538,7, FALSE) -> 1005 | AI11: =VLOOKUP($B11,'Cost prices'!$B$6:$H$538,7, FALSE) -> 1005 | AK11: =VLOOKUP($B11,'Cost prices'!$B$6:$H$538,7, FALSE) -> 1005 | AL11: =VLOOKUP($B11,'Cost prices'!$B$6:$H$538,7, FALSE) -> 1005 | AM11: =VLOOKUP($B11,'Cost prices'!$B$6:$H$538,7, FALSE)* IF('External Prices'!Y$28<>"No",2,1) -> 2010 | AO11: =VLOOKUP($B11,'Cost prices'!$B$6:$H$538,7, FALSE)* IF('External Prices'!Z$28<>"No",2,1) -> 1005 | AP11: =VLOOKUP($B11,'Cost prices'!$B$6:$H$538,7, FALSE)* IF('External Prices'!AA$28<>"No",2,1) -> 1005 | AQ11: =VLOOKUP($B11,'Cost prices'!$B$6:$H$538,7, FALSE)* IF('External Prices'!AB$28<>"No",2,1) -> 2010
B12: Shaft | E12: =VLOOKUP($B12,'Cost prices'!$B$6:$H$538,7, FALSE) -> Incl Seneberg | F12: =VLOOKUP($B12,'Cost prices'!$B$6:$H$538,7, FALSE) -> Incl Seneberg | H12: =VLOOKUP($B12,'Cost prices'!$B$6:$H$538,7, FALSE) -> Incl Seneberg | J12: =VLOOKUP($B12,'Cost prices'!$B$6:$H$538,7, FALSE) -> Incl Seneberg | L12: =VLOOKUP($B12,'Cost prices'!$B$6:$H$538,7, FALSE) -> Incl Seneberg | N12: =VLOOKUP($B12,'Cost prices'!$B$6:$H$538,7, FALSE) -> Incl Seneberg | P12: =VLOOKUP($B12,'Cost prices'!$B$6:$H$538,7, FALSE) -> Incl Seneberg | R12: =VLOOKUP($B12,'Cost prices'!$B$6:$H$538,7, FALSE) -> Incl Seneberg | T12: =VLOOKUP($B12,'Cost prices'!$B$6:$H$538,7, FALSE) -> Incl Seneberg | V12: =VLOOKUP($B12,'Cost prices'!$B$6:$H$538,7, FALSE) -> Incl Seneberg | X12: =VLOOKUP($B12,'Cost prices'!$B$6:$H$538,7, FALSE) -> Incl Seneberg | Z12: =VLOOKUP($B12,'Cost prices'!$B$6:$H$538,7, FALSE) -> Incl Seneberg | AB12: =VLOOKUP($B12,'Cost prices'!$B$6:$H$538,7, FALSE) -> Incl Seneberg | AD12: =VLOOKUP($B12,'Cost prices'!$B$6:$H$538,7, FALSE) -> Incl Seneberg | AE12: =VLOOKUP($B12,'Cost prices'!$B$6:$H$538,7, FALSE) -> Incl Seneberg | AF12: =VLOOKUP($B12,'Cost prices'!$B$6:$H$538,7, FALSE) -> Incl Seneberg | AH12: =VLOOKUP($B12,'Cost prices'!$B$6:$H$538,7, FALSE) -> Incl Seneberg | AI12: =VLOOKUP($B12,'Cost prices'!$B$6:$H$538,7, FALSE) -> Incl Seneberg | AK12: =VLOOKUP($B12,'Cost prices'!$B$6:$H$538,7, FALSE) -> Incl Seneberg | AL12: =VLOOKUP($B12,'Cost prices'!$B$6:$H$538,7, FALSE) -> Incl Seneberg | AM12: =VLOOKUP($B12,'Cost prices'!$B$6:$H$538,7, FALSE) -> Incl Seneberg | AO12: =VLOOKUP($B12,'Cost prices'!$B$6:$H$538,7, FALSE) -> Incl Seneberg | AP12: =VLOOKUP($B12,'Cost prices'!$B$6:$H$538,7, FALSE) -> Incl Seneberg | AQ12: =VLOOKUP($B12,'Cost prices'!$B$6:$H$538,7, FALSE) -> Incl Seneberg
B13: Dan Seneberg, Pump house fabrication | E13: =VLOOKUP($B13,'Cost prices'!$B$6:$H$538,7, FALSE) -> 4960.955 | F13: =VLOOKUP($B13,'Cost prices'!$B$6:$H$538,7, FALSE) -> 4960.955 | H13: =VLOOKUP($B13,'Cost prices'!$B$6:$H$538,7, FALSE) -> 4960.955 | J13: =VLOOKUP($B13,'Cost prices'!$B$6:$H$538,7, FALSE) -> 4960.955 | L13: =VLOOKUP($B13,'Cost prices'!$B$6:$H$538,7, FALSE) -> 4960.955 | N13: =VLOOKUP($B13,'Cost prices'!$B$6:$H$538,7, FALSE) -> 4960.955 | P13: =VLOOKUP($B13,'Cost prices'!$B$6:$H$538,7, FALSE) -> 4960.955 | R13: =VLOOKUP($B13,'Cost prices'!$B$6:$H$538,7, FALSE) -> 4960.955 | T13: =VLOOKUP($B13,'Cost prices'!$B$6:$H$538,7, FALSE) -> 4960.955 | V13: =VLOOKUP($B13,'Cost prices'!$B$6:$H$538,7, FALSE) -> 4960.955 | X13: =VLOOKUP($B13,'Cost prices'!$B$6:$H$538,7, FALSE) -> 4960.955 | Z13: =VLOOKUP($B13,'Cost prices'!$B$6:$H$538,7, FALSE) -> 4960.955
B14: Dan Seneberg, assemble and test | E14: =VLOOKUP($B14,'Cost prices'!$B$6:$H$538,7, FALSE) -> 8223.757 | F14: =VLOOKUP($B14,'Cost prices'!$B$6:$H$538,7, FALSE) -> 8223.757 | H14: =VLOOKUP($B14,'Cost prices'!$B$6:$H$538,7, FALSE) -> 8223.757 | J14: =VLOOKUP($B14,'Cost prices'!$B$6:$H$538,7, FALSE) -> 8223.757 | L14: =VLOOKUP($B14,'Cost prices'!$B$6:$H$538,7, FALSE) -> 8223.757 | N14: =VLOOKUP($B14,'Cost prices'!$B$6:$H$538,7, FALSE) -> 8223.757 | P14: =VLOOKUP($B14,'Cost prices'!$B$6:$H$538,7, FALSE) -> 8223.757 | R14: =VLOOKUP($B14,'Cost prices'!$B$6:$H$538,7, FALSE) -> 8223.757 | T14: =VLOOKUP($B14,'Cost prices'!$B$6:$H$538,7, FALSE) -> 8223.757 | V14: =VLOOKUP($B14,'Cost prices'!$B$6:$H$538,7, FALSE) -> 8223.757 | X14: =VLOOKUP($B14,'Cost prices'!$B$6:$H$538,7, FALSE) -> 8223.757 | Z14: =VLOOKUP($B14,'Cost prices'!$B$6:$H$538,7, FALSE) -> 8223.757 | AB14: =VLOOKUP($B14,'Cost prices'!$B$6:$H$538,7, FALSE) -> 8223.757 | AD14: =VLOOKUP($B14,'Cost prices'!$B$6:$H$538,7, FALSE) -> 8223.757 | AE14: =VLOOKUP($B14,'Cost prices'!$B$6:$H$538,7, FALSE) -> 8223.757 | AF14: =VLOOKUP($B14,'Cost prices'!$B$6:$H$538,7, FALSE) -> 8223.757 | AH14: =VLOOKUP($B14,'Cost prices'!$B$6:$H$538,7, FALSE) -> 8223.757 | AI14: =VLOOKUP($B14,'Cost prices'!$B$6:$H$538,7, FALSE) -> 8223.757 | AK14: =VLOOKUP($B14,'Cost prices'!$B$6:$H$538,7, FALSE) -> 8223.757 | AL14: =VLOOKUP($B14,'Cost prices'!$B$6:$H$538,7, FALSE) -> 8223.757 | AM14: =VLOOKUP($B14,'Cost prices'!$B$6:$H$538,7, FALSE) -> 8223.757 | AO14: =VLOOKUP($B14,'Cost prices'!$B$6:$H$538,7, FALSE) -> 8223.757 | AP14: =VLOOKUP($B14,'Cost prices'!$B$6:$H$538,7, FALSE) -> 8223.757 | AQ14: =VLOOKUP($B14,'Cost prices'!$B$6:$H$538,7, FALSE) -> 8223.757
B15: Dan Seneberg workshop, 35 holes | E15: =VLOOKUP($B15,'Cost prices'!$B$6:$H$538,7, FALSE) -> 14519.082 | F15: =VLOOKUP($B15,'Cost prices'!$B$6:$H$538,7, FALSE) -> 14519.082 | H15: =VLOOKUP($B15,'Cost prices'!$B$6:$H$538,7, FALSE) -> 14519.082 | J15: =VLOOKUP($B15,'Cost prices'!$B$6:$H$538,7, FALSE) -> 14519.082 | L15: =VLOOKUP($B15,'Cost prices'!$B$6:$H$538,7, FALSE) -> 14519.082 | N15: =VLOOKUP($B15,'Cost prices'!$B$6:$H$538,7, FALSE) -> 14519.082 | P15: =VLOOKUP($B15,'Cost prices'!$B$6:$H$538,7, FALSE) -> 14519.082 | R15: =VLOOKUP($B15,'Cost prices'!$B$6:$H$538,7, FALSE) -> 14519.082 | T15: =VLOOKUP($B15,'Cost prices'!$B$6:$H$538,7, FALSE) -> 14519.082 | V15: =VLOOKUP($B15,'Cost prices'!$B$6:$H$538,7, FALSE) -> 14519.082 | X15: =VLOOKUP($B15,'Cost prices'!$B$6:$H$538,7, FALSE) -> 14519.082
B16: Dan Seneberg workshop, 105 holes | Z16: =VLOOKUP($B16,'Cost prices'!$B$6:$H$538,7, FALSE) -> 16009.082 | AB16: =VLOOKUP($B16,'Cost prices'!$B$6:$H$538,7, FALSE) -> 16009.082 | AD16: =VLOOKUP($B16,'Cost prices'!$B$6:$H$538,7, FALSE) -> 16009.082 | AE16: =VLOOKUP($B16,'Cost prices'!$B$6:$H$538,7, FALSE)* IF('External Prices'!S$28<>"No",2,1) -> 16009.082 | AF16: =VLOOKUP($B16,'Cost prices'!$B$6:$H$538,7, FALSE)* IF('External Prices'!T$28<>"No",2,1) -> 16009.082 | AH16: =VLOOKUP($B16,'Cost prices'!$B$6:$H$538,7, FALSE) -> 16009.082 | AI16: =VLOOKUP($B16,'Cost prices'!$B$6:$H$538,7, FALSE) -> 16009.082 | AK16: =VLOOKUP($B16,'Cost prices'!$B$6:$H$538,7, FALSE) -> 16009.082 | AL16: =VLOOKUP($B16,'Cost prices'!$B$6:$H$538,7, FALSE) -> 16009.082 | AM16: =VLOOKUP($B16,'Cost prices'!$B$6:$H$538,7, FALSE)* IF('External Prices'!Y$28<>"No",2,1) -> 32018.163 | AO16: =VLOOKUP($B16,'Cost prices'!$B$6:$H$538,7, FALSE)* IF('External Prices'!Z$28<>"No",2,1) -> 16009.082 | AP16: =VLOOKUP($B16,'Cost prices'!$B$6:$H$538,7, FALSE)* IF('External Prices'!AA$28<>"No",2,1) -> 16009.082 | AQ16: =VLOOKUP($B16,'Cost prices'!$B$6:$H$538,7, FALSE)* IF('External Prices'!AB$28<>"No",2,1) -> 32018.163
A18: Danish supplys
B19: Water flush mixer parts
A20: RS components | B20: *Y-strainer | Z20: =VLOOKUP($B20,'Cost prices'!$B$6:$H$538,7, FALSE) -> 473.67 | AD20: =VLOOKUP($B20,'Cost prices'!$B$6:$H$538,7, FALSE) -> 473.67 | AE20: =VLOOKUP($B20,'Cost prices'!$B$6:$H$538,7, FALSE)* IF('External Prices'!S$28<>"No",2,1) -> 473.67 | AF20: =VLOOKUP($B20,'Cost prices'!$B$6:$H$538,7, FALSE)* IF('External Prices'!T$28<>"No",2,1) -> 473.67 | AH20: =VLOOKUP($B20,'Cost prices'!$B$6:$H$538,7, FALSE) -> 473.67 | AI20: =VLOOKUP($B20,'Cost prices'!$B$6:$H$538,7, FALSE) -> 473.67 | AK20: =VLOOKUP($B20,'Cost prices'!$B$6:$H$538,7, FALSE) -> 473.67 | AL20: =VLOOKUP($B20,'Cost prices'!$B$6:$H$538,7, FALSE) -> 473.67 | AM20: =VLOOKUP($B20,'Cost prices'!$B$6:$H$538,7, FALSE)* IF('External Prices'!Y$28<>"No",2,1) -> 947.34 | AO20: =VLOOKUP($B20,'Cost prices'!$B$6:$H$538,7, FALSE)* IF('External Prices'!Z$28<>"No",2,1) -> 473.67 | AP20: =VLOOKUP($B20,'Cost prices'!$B$6:$H$538,7, FALSE)* IF('External Prices'!AA$28<>"No",2,1) -> 473.67 | AQ20: =VLOOKUP($B20,'Cost prices'!$B$6:$H$538,7, FALSE)* IF('External Prices'!AB$28<>"No",2,1) -> 947.34 | BH20: =VLOOKUP($B20,'Cost prices'!$B$6:$H$538,7, FALSE) -> 473.67
A21: Bürkert | B21: *2/2-waY-solenoId valve, servo assisted 6213-EV-A10,0AAVAGM82-6-024/DC-10 *NA38 | Z21: =VLOOKUP($B21,'Cost prices'!$B$6:$H$538,7, FALSE) -> 2083.3209 | AD21: =VLOOKUP($B21,'Cost prices'!$B$6:$H$538,7, FALSE) -> 2083.3209 | AE21: =VLOOKUP($B21,'Cost prices'!$B$6:$H$538,7, FALSE)* IF('External Prices'!S$28<>"No",2,1) -> 2083.3209 | AF21: =VLOOKUP($B21,'Cost prices'!$B$6:$H$538,7, FALSE)* IF('External Prices'!T$28<>"No",2,1) -> 2083.3209 | AH21: =VLOOKUP($B21,'Cost prices'!$B$6:$H$538,7, FALSE) -> 2083.3209 | AI21: =VLOOKUP($B21,'Cost prices'!$B$6:$H$538,7, FALSE) -> 2083.3209 | AK21: =VLOOKUP($B21,'Cost prices'!$B$6:$H$538,7, FALSE) -> 2083.3209 | AL21: =VLOOKUP($B21,'Cost prices'!$B$6:$H$538,7, FALSE) -> 2083.3209 | AM21: =VLOOKUP($B21,'Cost prices'!$B$6:$H$538,7, FALSE)* IF('External Prices'!Y$28<>"No",2,1) -> 4166.6418 | AO21: =VLOOKUP($B21,'Cost prices'!$B$6:$H$538,7, FALSE)* IF('External Prices'!Z$28<>"No",2,1) -> 2083.3209 | AP21: =VLOOKUP($B21,'Cost prices'!$B$6:$H$538,7, FALSE)* IF('External Prices'!AA$28<>"No",2,1) -> 2083.3209 | AQ21: =VLOOKUP($B21,'Cost prices'!$B$6:$H$538,7, FALSE)* IF('External Prices'!AB$28<>"No",2,1) -> 4166.6418 | BH21: =VLOOKUP($B21,'Cost prices'!$B$6:$H$538,7, FALSE) -> 2083.3209
A22: Bürkert | B22: *Kabelstik 2518 28mm Form A UL approva 2518-A-BCS/UC-00-3-N50-00-0-00000 JLO4 | Z22: =VLOOKUP($B22,'Cost prices'!$B$6:$H$538,7, FALSE) -> 118.5213 | AD22: =VLOOKUP($B22,'Cost prices'!$B$6:$H$538,7, FALSE) -> 118.5213 | AE22: =VLOOKUP($B22,'Cost prices'!$B$6:$H$538,7, FALSE)* IF('External Prices'!S$28<>"No",2,1) -> 118.5213 | AF22: =VLOOKUP($B22,'Cost prices'!$B$6:$H$538,7, FALSE)* IF('External Prices'!T$28<>"No",2,1) -> 118.5213 | AH22: =VLOOKUP($B22,'Cost prices'!$B$6:$H$538,7, FALSE) -> 118.5213 | AI22: =VLOOKUP($B22,'Cost prices'!$B$6:$H$538,7, FALSE) -> 118.5213 | AK22: =VLOOKUP($B22,'Cost prices'!$B$6:$H$538,7, FALSE) -> 118.5213 | AL22: =VLOOKUP($B22,'Cost prices'!$B$6:$H$538,7, FALSE) -> 118.5213 | AM22: =VLOOKUP($B22,'Cost prices'!$B$6:$H$538,7, FALSE)* IF('External Prices'!Y$28<>"No",2,1) -> 237.0426 | AO22: =VLOOKUP($B22,'Cost prices'!$B$6:$H$538,7, FALSE)* IF('External Prices'!Z$28<>"No",2,1) -> 118.5213 | AP22: =VLOOKUP($B22,'Cost prices'!$B$6:$H$538,7, FALSE)* IF('External Prices'!AA$28<>"No",2,1) -> 118.5213 | AQ22: =VLOOKUP($B22,'Cost prices'!$B$6:$H$538,7, FALSE)* IF('External Prices'!AB$28<>"No",2,1) -> 237.0426 | BH22: =VLOOKUP($B22,'Cost prices'!$B$6:$H$538,7, FALSE) -> 118.5213
A23: DVC | B23: Needel valve | Z23: =VLOOKUP($B23,'Cost prices'!$B$6:$H$538,7, FALSE) -> 593 | AD23: =VLOOKUP($B23,'Cost prices'!$B$6:$H$538,7, FALSE) -> 593 | AE23: =VLOOKUP($B23,'Cost prices'!$B$6:$H$538,7, FALSE)* IF('External Prices'!S$28<>"No",2,1) -> 593 | AF23: =VLOOKUP($B23,'Cost prices'!$B$6:$H$538,7, FALSE)* IF('External Prices'!T$28<>"No",2,1) -> 593 | AH23: =VLOOKUP($B23,'Cost prices'!$B$6:$H$538,7, FALSE) -> 593 | AI23: =VLOOKUP($B23,'Cost prices'!$B$6:$H$538,7, FALSE) -> 593 | AK23: =VLOOKUP($B23,'Cost prices'!$B$6:$H$538,7, FALSE) -> 593 | AL23: =VLOOKUP($B23,'Cost prices'!$B$6:$H$538,7, FALSE) -> 593 | AM23: =VLOOKUP($B23,'Cost prices'!$B$6:$H$538,7, FALSE)* IF('External Prices'!Y$28<>"No",2,1) -> 1186 | AO23: =VLOOKUP($B23,'Cost prices'!$B$6:$H$538,7, FALSE)* IF('External Prices'!Z$28<>"No",2,1) -> 593 | AP23: =VLOOKUP($B23,'Cost prices'!$B$6:$H$538,7, FALSE)* IF('External Prices'!AA$28<>"No",2,1) -> 593 | AQ23: =VLOOKUP($B23,'Cost prices'!$B$6:$H$538,7, FALSE)* IF('External Prices'!AB$28<>"No",2,1) -> 1186 | BH23: =VLOOKUP($B23,'Cost prices'!$B$6:$H$538,7, FALSE) -> 593
A24: DVC | B24: Ball Valve (full bore) | H24: Incl Brian
A25: FOOT | B25: FOOT | E25: Incl Brian | F25: Incl Brian | J25: Incl Brian | L25: =IFERROR( VLOOKUP( IF('External Prices'!I18="MARTIN","M16x2 ø60",IF('External Prices'!I18="NGI","XH65-M16 x 150/85-M16 x 50","")), 'Cost prices'!$B$6:$H$376, 7, FALSE )*7, "") | N25: =IFERROR( VLOOKUP( IF('External Prices'!J18="MARTIN","M16x2 ø60",IF('External Prices'!J18="NGI","XH65-M16 x 150/85-M16 x 50","")), 'Cost prices'!$B$6:$H$376, 7, FALSE )*4, "") | P25: =IFERROR( VLOOKUP( IF('External Prices'!K18="MARTIN","M16x2 ø60",IF('External Prices'!K18="NGI","XH65-M16 x 150/85-M16 x 50","")), 'Cost prices'!$B$6:$H$376, 7, FALSE )*4, "") | R25: =IFERROR( VLOOKUP( IF('External Prices'!L18="MARTIN","M16x2 ø60",IF('External Prices'!L18="NGI","XH65-M16 x 150/85-M16 x 50","")), 'Cost prices'!$B$6:$H$376, 7, FALSE )*7, "") -> 2056.67 | T25: =VLOOKUP($B25,'Cost prices'!$B$6:$H$376,7, FALSE)*S25 -> #N/A | V25: =IFERROR( VLOOKUP( IF('External Prices'!N18="MARTIN","M16x2 ø60",IF('External Prices'!N18="NGI","XH65-M16 x 150/85-M16 x 50","")), 'Cost prices'!$B$6:$H$376, 7, FALSE )*7, "") -> 2056.67 | BE25: ='Cost prices'!$H$244*4 -> 842.7784 | BL25: ='Cost prices'!$H$244*4 -> 842.7784
B26: xx kW motor | E26: =VLOOKUP('External Prices'!E14,'Cost prices'!$B$6:$H$538,7, FALSE) -> 11970.57 | F26: =VLOOKUP('External Prices'!F14,'Cost prices'!$B$6:$H$538,7, FALSE) -> 11970.57 | H26: =VLOOKUP('External Prices'!G14,'Cost prices'!$B$6:$H$538,7, FALSE) -> 11970.57 | J26: =VLOOKUP('External Prices'!H14,'Cost prices'!$B$6:$H$538,7, FALSE) -> 11970.57 | L26: =VLOOKUP('External Prices'!I14,'Cost prices'!$B$6:$H$538,7, FALSE) -> 9301.92 | N26: =VLOOKUP('External Prices'!J14,'Cost prices'!$B$6:$H$538,7, FALSE) -> 9301.92 | P26: =VLOOKUP('External Prices'!K14,'Cost prices'!$B$6:$H$538,7, FALSE) -> 11970.57 | R26: =VLOOKUP('External Prices'!L14,'Cost prices'!$B$6:$H$538,7, FALSE) -> 11970.57 | T26: =VLOOKUP('External Prices'!L14,'Cost prices'!$B$6:$H$538,7, FALSE) -> 11970.57 | V26: =VLOOKUP('External Prices'!N14,'Cost prices'!$B$6:$H$538,7, FALSE) -> 11970.57 | X26: =VLOOKUP('External Prices'!O14,'Cost prices'!$B$6:$H$538,7, FALSE) -> 11970.57 | Z26: =VLOOKUP('External Prices'!P14,'Cost prices'!$B$6:$H$538,7, FALSE) -> 11970.57 | AB26: =9473+1500 -> 10973 | AD26: =VLOOKUP('External Prices'!R14,'Cost prices'!$B$6:$H$538,7, FALSE) -> 11970.57 | AE26: =VLOOKUP('External Prices'!S14,'Cost prices'!$B$6:$H$538,7, FALSE)* IF('External Prices'!S$28<>"No",2,1) -> 11970.57 | AF26: =VLOOKUP('External Prices'!T14,'Cost prices'!$B$6:$H$538,7, FALSE)* IF('External Prices'!T$28<>"No",2,1) -> 11970.57 | AH26: =VLOOKUP('External Prices'!U14,'Cost prices'!$B$6:$H$538,7, FALSE) -> 11970.57 | AI26: =VLOOKUP('External Prices'!V14,'Cost prices'!$B$6:$H$538,7, FALSE) -> 11970.57 | AK26: =VLOOKUP('External Prices'!W14,'Cost prices'!$B$6:$H$538,7, FALSE) -> 11970.57 | AL26: =VLOOKUP('External Prices'!X14,'Cost prices'!$B$6:$H$538,7, FALSE) -> 17983.92 | AM26: =VLOOKUP('External Prices'!Y14,'Cost prices'!$B$6:$H$538,7, FALSE)* IF('External Prices'!Y$28<>"No",2,1) -> 32995.84 | AO26: =VLOOKUP('External Prices'!Z14,'Cost prices'!$B$6:$H$538,7, FALSE)* IF('External Prices'!Z$28<>"No",2,1) -> 11970.57 | AP26: =VLOOKUP('External Prices'!AA14,'Cost prices'!$B$6:$H$538,7, FALSE)* IF('External Prices'!AA$28<>"No",2,1) -> 11970.57 | AQ26: =VLOOKUP('External Prices'!AB14,'Cost prices'!$B$6:$H$538,7, FALSE)* IF('External Prices'!AB$28<>"No",2,1) -> 32995.84 | AS26: =VLOOKUP(AS$1,'Cost prices'!$B$6:$H$538,7, FALSE) -> 13054 | AT26: =VLOOKUP(AT$1,'Cost prices'!$B$6:$H$538,7, FALSE) -> 14016 | AU26: =VLOOKUP(AU$1,'Cost prices'!$B$6:$H$538,7, FALSE) -> 14978 | AV26: =VLOOKUP(AV$1,'Cost prices'!$B$6:$H$538,7, FALSE) -> 17663 | AW26: =VLOOKUP(AW$1,'Cost prices'!$B$6:$H$538,7, FALSE) -> 11990
A27: Norland | B27: Control cabinet (VN version) | AS27: =VLOOKUP($B27,'Cost prices'!$B$6:$H$538,7, FALSE) -> 12612.03 | AT27: =VLOOKUP($B27,'Cost prices'!$B$6:$H$538,7, FALSE) -> 12612.03 | AU27: =VLOOKUP($B27,'Cost prices'!$B$6:$H$538,7, FALSE) -> 12612.03 | AV27: =VLOOKUP($B27,'Cost prices'!$B$6:$H$538,7, FALSE) -> 12612.03 | AW27: =VLOOKUP($B27,'Cost prices'!$B$6:$H$538,7, FALSE) -> 12612.03 | AX27: On display | AY27: On display | AZ27: On display | BA27: On display
A28: Eletrician | B28: Cables inst (part of Brian cost) | AV28: =$C$28 -> 0
B29: SMS, Clamp, Flange | BI29: 500
B30: xx kW frequency Inverter | E30: NOT INCLUDED | F30: NOT INCLUDED | H30: NOT INCLUDED | J30: NOT INCLUDED | L30: NOT INCLUDED | N30: NOT INCLUDED | P30: NOT INCLUDED | R30: NOT INCLUDED | T30: NOT INCLUDED | V30: NOT INCLUDED | X30: NOT INCLUDED | Z30: NOT INCLUDED | AB30: NOT INCLUDED | AD30: NOT INCLUDED | AE30: NOT INCLUDED | AF30: NOT INCLUDED | AH30: NOT INCLUDED | AI30: NOT INCLUDED | AK30: NOT INCLUDED | AL30: NOT INCLUDED | AM30: NOT INCLUDED | AO30: NOT INCLUDED | AP30: NOT INCLUDED | AQ30: NOT INCLUDED | AS30: Included | AT30: Included | AU30: Included | AV30: Included | AW30: Included | AX30: =VLOOKUP(AX$1,'Cost prices'!$B$6:$H$538,7, FALSE) -> 9683.25 | AY30: =VLOOKUP(AY$1,'Cost prices'!$B$6:$H$538,7, FALSE) -> 11919.75 | AZ30: =VLOOKUP(AZ$1,'Cost prices'!$B$6:$H$538,7, FALSE) -> 13715.25 | BA30: =VLOOKUP(BA$1,'Cost prices'!$B$6:$H$538,7, FALSE) -> 15510.75
A31: HTEN | B31: xx kW frequency Inverter | BB31: ='Cost prices'!H388 -> 138517.23 | BC31: ='Cost prices'!H389 -> 126658.56 | BD31: ='Cost prices'!H408 -> 180863.25
A33: Brian | B33: Mixer complete unit [incl unit parts] | E33: =VLOOKUP(E$1,'Cost prices'!$B$6:$H$538,7, FALSE) -> 14905 | F33: =VLOOKUP(F$1,'Cost prices'!$B$6:$H$538,7, FALSE) -> 26290 | H33: =VLOOKUP(H$1,'Cost prices'!$B$6:$H$538,7, FALSE) -> 51590 | J33: =VLOOKUP(J$1,'Cost prices'!$B$6:$H$538,7, FALSE) -> 90310
B34: Mesh | BG34: =VLOOKUP(BG$1,'Cost prices'!$B$6:$H$538,7, FALSE) -> 4796 | BK34: 1500
B35: Table | BE35: =VLOOKUP($B35,'Cost prices'!$B$6:$H$538,7, FALSE) -> 13134 | BK35: =8*600 -> 4800
B36: Control system (fitting/conection of panel) | AS36: =VLOOKUP($B36,'Cost prices'!$B$6:$H$538,7, FALSE) -> 5720 | AT36: =VLOOKUP($B36,'Cost prices'!$B$6:$H$538,7, FALSE) -> 5720 | AU36: =VLOOKUP($B36,'Cost prices'!$B$6:$H$538,7, FALSE) -> 5720 | AV36: =VLOOKUP($B36,'Cost prices'!$B$6:$H$538,7, FALSE) -> 5720 | AW36: =VLOOKUP($B36,'Cost prices'!$B$6:$H$538,7, FALSE) -> 5720 | AX36: =VLOOKUP($B36,'Cost prices'!$B$6:$H$538,7, FALSE) -> 5720 | AY36: =VLOOKUP($B36,'Cost prices'!$B$6:$H$538,7, FALSE) -> 5720 | AZ36: =VLOOKUP($B36,'Cost prices'!$B$6:$H$538,7, FALSE) -> 5720 | BA36: =VLOOKUP($B36,'Cost prices'!$B$6:$H$538,7, FALSE) -> 5720
B37: Test / packing
B38: Time (hourly rate) | BI38: 500
B39: Seal water | BH39: =VLOOKUP($B39,'Cost prices'!$B$6:$H$538,7, FALSE) -> 720.5
B41: Parts | W41: PCS | Y41: Pcs | AC41: PCS | AG41: PCS | AJ41: PCS | AN41: PCS
A42: Bolts | B42: Nut NDXH M8, AISI 316 | AC42: 0 | AD42: =IF($AC42="x","incl",VLOOKUP($B42,'Cost prices'!$B$6:$H$538,7,FALSE)*$AC42) -> 0 | AE42: =IF($AC42="x","incl",VLOOKUP($B42,'Cost prices'!$B$6:$H$538,7,FALSE)*$AC42) -> 0 | AF42: =IF($AC42="x","incl",VLOOKUP($B42,'Cost prices'!$B$6:$H$538,7,FALSE)*$AC42) -> 0 | AG42: 40 | AH42: =IF($AG42="x","incl",VLOOKUP($B42,'Cost prices'!$B$6:$H$538,7,FALSE)*$AG42) -> 1090.16 | AI42: =IF($AG42="x","incl",VLOOKUP($B42,'Cost prices'!$B$6:$H$538,7,FALSE)*$AG42) -> 1090.16 | AJ42: 40 | AK42: =IF($AJ42="x","incl",VLOOKUP($B42,'Cost prices'!$B$6:$H$538,7,FALSE)*$AJ42) -> 1090.16 | AL42: =IF($AJ42="x","incl",VLOOKUP($B42,'Cost prices'!$B$6:$H$538,7,FALSE)*$AJ42) -> 1090.16 | AM42: =IF($AJ42="x","incl",VLOOKUP($B42,'Cost prices'!$B$6:$H$538,7,FALSE)*$AJ42) -> 1090.16 | AN42: 40 | AO42: =IF($AN42="x","incl",VLOOKUP($B42,'Cost prices'!$B$6:$H$538,7,FALSE)*$AN42) -> 1090.16 | AP42: =IF($AN42="x","incl",VLOOKUP($B42,'Cost prices'!$B$6:$H$538,7,FALSE)*$AN42) -> 1090.16 | AQ42: =IF($AN42="x","incl",VLOOKUP($B42,'Cost prices'!$B$6:$H$538,7,FALSE)*$AN42) -> 1090.16
A43: Top | B43: Site glass with wiber | Z43: {=IFERROR( VLOOKUP( _xlfn.SWITCH('External Prices'!P19, "EBORA EU","SITE GLASS WITH WIPER", "NO NAME CN","SITE GLASS CN", "" ), 'Cost prices'!$B$6:$H$376,7,FALSE )*1, "")} -> 6528.5444 | AD43: {=IFERROR( VLOOKUP( _xlfn.SWITCH('External Prices'!R19, "EBORA EU","SITE GLASS WITH WIPER", "NO NAME CN","SITE GLASS CN", "" ), 'Cost prices'!$B$6:$H$376,7,FALSE )*1, "")} | AE43: {=IFERROR( VLOOKUP( _xlfn.SWITCH('External Prices'!S19, "EBORA EU","SITE GLASS WITH WIPER", "NO NAME CN","SITE GLASS CN", "" ), 'Cost prices'!$B$6:$H$376,7,FALSE )*1, "")} | AF43: {=IFERROR( VLOOKUP( _xlfn.SWITCH('External Prices'!T19, "EBORA EU","SITE GLASS WITH WIPER", "NO NAME CN","SITE GLASS CN", "" ), 'Cost prices'!$B$6:$H$376,7,FALSE )*1, "")} | AH43: {=IFERROR( VLOOKUP( _xlfn.SWITCH('External Prices'!U19, "EBORA EU","SITE GLASS WITH WIPER", "NO NAME CN","SITE GLASS CN", "" ), 'Cost prices'!$B$6:$H$376,7,FALSE )*1, "")} -> 6528.5444 | AI43: {=IFERROR( VLOOKUP( _xlfn.SWITCH('External Prices'!V19, "EBORA EU","SITE GLASS WITH WIPER", "NO NAME CN","SITE GLASS CN", "" ), 'Cost prices'!$B$6:$H$376,7,FALSE )*1, "")} -> 6528.5444 | AK43: {=IFERROR( VLOOKUP( _xlfn.SWITCH('External Prices'!W19, "EBORA EU","SITE GLASS WITH WIPER", "NO NAME CN","SITE GLASS CN", "" ), 'Cost prices'!$B$6:$H$376,7,FALSE )*1, "")} -> 6528.5444 | AL43: {=IFERROR( VLOOKUP( _xlfn.SWITCH('External Prices'!X19, "EBORA EU","SITE GLASS WITH WIPER", "NO NAME CN","SITE GLASS CN", "" ), 'Cost prices'!$B$6:$H$376,7,FALSE )*1, "")} -> 6528.5444 | AM43: {=IFERROR( VLOOKUP( _xlfn.SWITCH('External Prices'!Y19, "EBORA EU","SITE GLASS WITH WIPER", "NO NAME CN","SITE GLASS CN", "" ), 'Cost prices'!$B$6:$H$376,7,FALSE )*1, "")} -> 6528.5444 | AO43: {=IFERROR( VLOOKUP( _xlfn.SWITCH('External Prices'!Z19, "EBORA EU","SITE GLASS WITH WIPER", "NO NAME CN","SITE GLASS CN", "" ), 'Cost prices'!$B$6:$H$376,7,FALSE )*1, "")} -> 6528.5444 | AP43: {=IFERROR( VLOOKUP( _xlfn.SWITCH('External Prices'!AA19, "EBORA EU","SITE GLASS WITH WIPER", "NO NAME CN","SITE GLASS CN", "" ), 'Cost prices'!$B$6:$H$376,7,FALSE )*1, "")} -> 6528.5444 | AQ43: {=IFERROR( VLOOKUP( _xlfn.SWITCH('External Prices'!AB19, "EBORA EU","SITE GLASS WITH WIPER", "NO NAME CN","SITE GLASS CN", "" ), 'Cost prices'!$B$6:$H$376,7,FALSE )*1, "")} -> 6528.5444
...

Sheet Rules
AL3: 1 | AM3: 2 | AN3: 3 | AO3: 4 | AP3: 5 | AQ3: 6 | AR3: 7 | AS3: 8 | AT3: 9 | AU3: 10 | AV3: 11 | AW3: 12 | AX3: 13 | AY3: 14 | AZ3: 15 | BA3: 16 | BB3: 17
A5: Country | B5: Negotiation | C5: Agent | D5: Country | F5: Months | H5: Selection | I5: Direct client | J5: Factor | K5: Design level | L5: Factor | M5: Competition | N5: Factor | O5: Power | P5: Overruling | Q5: Fcountry | R5: Fagent | S5: Fnegotiation | T5: Forderwhen | U5: Fcompetition | V5: Fclient | W5: Fdesignlevel | X5: Pump | Z5: Overruling | AA5: Fcountry | AB5: Fagent | AC5: Fnegotiation | AD5: Forderwhen | AE5: Fcompetition | AF5: Fclient | AG5: Fdesignlevel | AH5: Tank | AM5: Margin | AQ5: Hours | AV5: Quality Control
A6: Afghanistan | B6: 0.05 | C6: 0.1 | D6: 0.02 | F6: 2025 | G6: 0.01 | H6: Yes | I6: Any w. Agent | J6: 0.02 | K6: Standard | L6: 0 | M6: Standard | N6: 0 | O6: 11 kW | P6: None | Z6: None | AM6: DK | AN6: SG | AO6: VN | AP6: Eng | AQ6: D&E | AR6: Eng | AS6: Manual | AT6: Project M | AU6: Total | AV6: Hoang Lam FAT - Chinh | AW6: Hoang Lam FAT short - Kannan | AX6: Hoang Lam FAT - Kannan | AY6: Hoang Lam FAT - PM | AZ6: Hoang Lam FAT - HL staff | BA6: U3S FAT - DK | BB6: Training materials
A7: Albania | B7: 0.05 | C7: 0.1 | D7: 0.02 | F7: 2026 | G7: 0.05 | H7: No | I7: Agent | J7: 0.02 | K7: Advanced | L7: 0.05 | M7: Advanced | N7: 0.075 | O7: 15 kW | P7: Walk away | Q7: 0.001 | R7: 0 | S7: 0 | T7: 0 | U7: 0 | V7: 0 | W7: 0 | X7: =SUM(Q7:W7) -> 0.001 | Z7: Walk away | AA7: 0.001 | AB7: 0 | AC7: 0 | AD7: 0 | AE7: 0 | AF7: 0 | AG7: 0 | AH7: =SUM(AA7:AG7) -> 0.001 | AL7: Shear | AM7: 0.15 | AN7: 0.15 | AO7: 0.15 | AP7: 0.15 | AQ7: 4 | AR7: 4 | AS7: 4 | AT7: 12 | AU7: =SUM(AQ7:AT7) -> 24 | AV7: 0 | AW7: 0 | AX7: 0 | AY7: 0 | AZ7: 0 | BA7: 1 | BB7: 0
A8: Algeria | B8: 0.05 | C8: 0.1 | D8: 0.02 | I8: End client w/o Agent | J8: 0.075 | O8: 18.5 kW | P8: -- Tier 1 -- | Z8: -- Tier 1 -- | AL8: Shear L | AM8: 0.15 | AN8: 0.15 | AO8: 0.15 | AP8: 0.15 | AQ8: 4 | AR8: 4 | AS8: 4 | AT8: 12 | AU8: =SUM(AQ8:AT8) -> 24 | AV8: 0 | AW8: 0 | AX8: 0 | AY8: 0 | AZ8: 0 | BA8: 1 | BB8: 0
A9: Andorra | B9: 0.05 | C9: 0.1 | D9: 0.02 | I9: Engineering Corp w/o Agent | J9: 0.05 | O9: 22 kW | P9: Kesmo | Q9: 0.01 | R9: 0 | S9: 0.02 | T9: 0.02 | U9: 0 | V9: 0 | W9: 0 | X9: =SUM(Q9:W9) -> 0.05 | Z9: Kesmo | AA9: 0.01 | AB9: 0 | AC9: 0.02 | AD9: 0.02 | AE9: 0.05 | AF9: 0 | AG9: 0 | AH9: =SUM(AA9:AG9) -> 0.1 | AL9: Injector | AM9: 0.15 | AN9: 0.18 | AO9: 0.18 | AP9: 0.18 | AQ9: 4 | AR9: 4 | AS9: 4 | AT9: 12 | AU9: =SUM(AQ9:AT9) -> 24 | AV9: 0 | AW9: 0 | AX9: 0 | AY9: 0 | AZ9: 0 | BA9: 1 | BB9: 0
A10: Angola | B10: 0.05 | C10: 0.1 | D10: 0.02 | I10: MNC w/o Agent | J10: 0.05 | O10: 30 kW | P10: RRPE | Q10: 0.01 | R10: 0 | S10: 0.02 | T10: 0.02 | U10: 0 | V10: 0 | W10: 0 | X10: =SUM(Q10:W10) -> 0.05 | Z10: RRPE | AA10: 0.01 | AB10: 0 | AC10: 0.02 | AD10: 0.02 | AE10: 0.05 | AF10: 0 | AG10: 0 | AH10: =SUM(AA10:AG10) -> 0.1 | AL10: Vortex | AM10: 0.2 | AN10: 0.25 | AO10: 0.25 | AP10: 0.3 | AQ10: 4 | AR10: 4 | AS10: 4 | AT10: 12 | AU10: =SUM(AQ10:AT10) -> 24 | AV10: 0 | AW10: 0 | AX10: 0 | AY10: 0 | AZ10: 0 | BA10: 1 | BB10: 0
AL11: Injector site assemble | AM11: 0.15 | AN11: 0.15 | AO11: 0.15 | AP11: 0.15 | AQ11: 4 | AR11: 4 | AS11: 4 | AT11: 12 | AU11: =SUM(AQ11:AT11) -> 24 | AV11: 0 | AW11: 0 | AX11: 0 | AY11: 0 | AZ11: 0 | BA11: 0 | BB11: 0
A12: Antigua and Barbuda | B12: 0.05 | C12: 0.1 | D12: 0.02 | O12: 45 kW | P12: CSP | Q12: 0.01 | R12: 0 | S12: 0.02 | T12: 0.02 | U12: 0 | V12: 0 | W12: 0 | X12: =SUM(Q12:W12) -> 0.05 | Z12: CSP | AA12: 0.01 | AB12: 0 | AC12: 0.02 | AD12: 0.02 | AE12: 0.05 | AF12: 0 | AG12: 0 | AH12: =SUM(AA12:AG12) -> 0.1 | AL12: Shear VN | AM12: 0.15 | AN12: 0.15 | AO12: 0.15 | AP12: 0.15 | AQ12: 4 | AR12: 4 | AS12: 4 | AT12: 12 | AU12: =SUM(AQ12:AT12) -> 24 | AV12: 0 | AW12: 1 | AX12: 0 | AY12: 0 | AZ12: 0.5 | BA12: 0 | BB12: 0
A13: Argentina | B13: 0.05 | C13: 0.1 | D13: 0.02 | O13: 55 kW | P13: GDProcessDesign | Q13: 0.01 | R13: 0 | S13: 0.02 | T13: 0.02 | U13: 0 | V13: 0 | W13: 0 | X13: =SUM(Q13:W13) -> 0.05 | Z13: GDProcessDesign | AA13: 0.01 | AB13: 0 | AC13: 0.02 | AD13: 0.02 | AE13: 0.05 | AF13: 0 | AG13: 0 | AH13: =SUM(AA13:AG13) -> 0.1 | AL13: Loop VN | AM13: 0.15 | AN13: 0.15 | AO13: 0.15 | AP13: 0.15 | AQ13: 4 | AR13: 4 | AS13: 4 | AT13: 12 | AU13: =SUM(AQ13:AT13) -> 24 | AV13: 0 | AW13: 1 | AX13: 0 | AY13: 0 | AZ13: 0.5 | BA13: 0 | BB13: 0
A14: Armenia | B14: 0.05 | C14: 0.1 | D14: 0.02 | H14: Selection | O14: 75 kW | P14: PDP | Q14: 0.01 | R14: 0 | S14: 0.02 | T14: 0.02 | U14: 0 | V14: 0 | W14: 0 | X14: =SUM(Q14:W14) -> 0.05 | Z14: PDP | AA14: 0.01 | AB14: 0 | AC14: 0.02 | AD14: 0.02 | AE14: 0.05 | AF14: 0 | AG14: 0 | AH14: =SUM(AA14:AG14) -> 0.1 | AL14: Injector VN | AM14: 0.15 | AN14: 0.15 | AO14: 0.15 | AP14: 0.15 | AQ14: 4 | AR14: 4 | AS14: 4 | AT14: 12 | AU14: =SUM(AQ14:AT14) -> 24 | AV14: 0 | AW14: 1 | AX14: 0 | AY14: 0 | AZ14: 0.5 | BA14: 0 | BB14: 0
A15: Australia | B15: 0.05 | C15: 0.1 | D15: 0.02 | H15: 0 | O15: 90 kW | P15: Hyprosys | Q15: 0.01 | R15: 0 | S15: 0.02 | T15: 0.02 | U15: 0 | V15: 0 | W15: 0 | X15: =SUM(Q15:W15) -> 0.05 | Z15: Hyprosys | AA15: 0.01 | AB15: 0 | AC15: 0.02 | AD15: 0.02 | AE15: 0.05 | AF15: 0 | AG15: 0 | AH15: =SUM(AA15:AG15) -> 0.1 | AL15: Vortex VN | AM15: 0.15 | AN15: 0.15 | AO15: 0.15 | AP15: 0.15 | AQ15: 8 | AR15: 8 | AS15: 8 | AT15: 24 | AU15: =SUM(AQ15:AT15) -> 48 | AV15: 0 | AW15: 1 | AX15: 0 | AY15: 0 | AZ15: 0.5 | BA15: 0 | BB15: 0
A16: Austria | B16: 0.05 | C16: 0.1 | D16: 0.02 | H16: 1 | O16: 110 kW | P16: -- Tier 2 -- | Z16: -- Tier 2 -- | AL16: Vortex VN 800 | AM16: 0.25 | AN16: 0.25 | AO16: 0.3 | AP16: 0.3 | AQ16: 40 | AR16: 16 | AS16: 16 | AT16: 24 | AU16: =SUM(AQ16:AT16) -> 96 | AV16: 0 | AW16: 1 | AX16: 0 | AY16: 0 | AZ16: 0.5 | BA16: 0 | BB16: 0
A17: Azerbaijan | B17: 0.05 | C17: 0.1 | D17: 0.02 | H17: 2 | P17: Stig T | Q17: 0 | R17: 0.06 | S17: 0.025 | T17: 0 | U17: 0 | V17: 0 | W17: 0 | X17: =SUM(Q17:W17) -> 0.085 | Z17: Stig T | AA17: 0 | AB17: 0.1 | AC17: 0.025 | AD17: 0.01 | AE17: 0 | AF17: 0.01 | AG17: 0.01 | AH17: =SUM(AA17:AG17) -> 0.155 | AL17: Vortex Vacuum 2000 | AM17: 0.25 | AN17: 0.25 | AO17: 0.3 | AP17: 0.3 | AQ17: 80 | AR17: 40 | AS17: 40 | AT17: 80 | AU17: =SUM(AQ17:AT17) -> 240 | AV17: 0 | AW17: 0 | AX17: 1 | AY17: 1 | AZ17: 2 | BA17: 0 | BB17: 0
A18: Bahamas | B18: 0.05 | C18: 0.1 | D18: 0.02 | H18: 3 | P18: Scanimix | Q18: 0.01 | R18: 0.1 | S18: 0.025 | T18: 0.02 | U18: 0 | V18: 0 | W18: 0 | X18: =SUM(Q18:W18) -> 0.155 | Z18: Scanimix | AA18: 0.01 | AB18: 0.1 | AC18: 0.025 | AD18: 0.02 | AE18: 0.02 | AF18: 0.02 | AG18: 0.01 | AH18: =SUM(AA18:AG18) -> 0.205 | AL18: Bottom Shear | AM18: 0.3 | AN18: 0.3 | AO18: 0.3 | AP18: 0.3 | AQ18: 0 | AR18: 0 | AS18: 0 | AT18: 20 | AU18: =SUM(AQ18:AT18) -> 20 | AV18: 0 | AW18: 0 | AX18: 0 | AY18: 0 | AZ18: 0 | BA18: 0 | BB18: 0
A19: Bahrain | B19: 0.05 | C19: 0.1 | D19: 0.02 | H19: 4 | P19: mp-process | Q19: 0.01 | R19: 0.1 | S19: 0.025 | T19: 0.02 | U19: 0 | V19: 0 | W19: 0 | X19: =SUM(Q19:W19) -> 0.155 | Z19: mp-process | AA19: 0.01 | AB19: 0.1 | AC19: 0.025 | AD19: 0.02 | AE19: 0.02 | AF19: 0.02 | AG19: 0.01 | AH19: =SUM(AA19:AG19) -> 0.205 | AL19: Injector VN - TABLE ASSEMBLY | AM19: 0.15 | AN19: 0.15 | AO19: 0.15 | AP19: 0.15
A20: Bangladesh | B20: 0.05 | C20: 0.1 | D20: 0.02 | P20: Gabriel Urso | Q20: 0.01 | R20: 0.1 | S20: 0.025 | T20: 0.02 | U20: 0 | V20: 0 | W20: 0 | X20: =SUM(Q20:W20) -> 0.155 | Z20: Gabriel Urso | AA20: 0.01 | AB20: 0.1 | AC20: 0.025 | AD20: 0.02 | AE20: 0.02 | AF20: 0.02 | AG20: 0.01 | AH20: =SUM(AA20:AG20) -> 0.205 | AL20: LC 500 | AM20: 0.21 | AN20: 0.21 | AO20: 0.23 | AP20: 0.3 | AQ20: 16 | AR20: 16 | AS20: 16 | AT20: 24 | AU20: =SUM(AQ20:AT20) -> 72 | AV20: 0 | AW20: 1 | AX20: 0 | AY20: 0 | AZ20: 0.5 | BA20: 0 | BB20: 0
A21: Barbados | B21: 0.05 | C21: 0.1 | D21: 0.02 | P21: spa-alimentos | Q21: 0.01 | R21: 0.1 | S21: 0.025 | T21: 0.02 | U21: 0 | V21: 0 | W21: 0 | X21: =SUM(Q21:W21) -> 0.155 | Z21: spa-alimentos | AA21: 0.01 | AB21: 0.1 | AC21: 0.025 | AD21: 0.02 | AE21: 0.02 | AF21: 0.02 | AG21: 0.01 | AH21: =SUM(AA21:AG21) -> 0.205 | AL21: LC 1000 | AM21: 0.21 | AN21: 0.21 | AO21: 0.23 | AP21: 0.3 | AQ21: 16 | AR21: 16 | AS21: 16 | AT21: 24 | AU21: =SUM(AQ21:AT21) -> 72 | AV21: 0 | AW21: 1 | AX21: 0 | AY21: 0 | AZ21: 0.5 | BA21: 0 | BB21: 0
A22: Belarus | B22: 0.05 | C22: 0.1 | D22: 0.02 | I22: Mark-up additionals | P22: Morten Nielsen | Q22: 0.01 | R22: 0.1 | S22: 0.01 | T22: 0.02 | U22: 0 | V22: 0 | W22: 0 | X22: =SUM(Q22:W22) -> 0.14 | Z22: Morten Nielsen | AA22: 0.01 | AB22: 0.1 | AC22: 0.01 | AD22: 0.02 | AE22: 0 | AF22: 0 | AG22: 0 | AH22: =SUM(AA22:AG22) -> 0.14 | AL22: LC 3000 | AM22: 0.21 | AN22: 0.21 | AO22: 0.23 | AP22: 0.3 | AQ22: 24 | AR22: 16 | AS22: 16 | AT22: 24 | AU22: =SUM(AQ22:AT22) -> 80 | AV22: 0 | AX22: 1 | AY22: 0 | AZ22: 1 | BA22: 0 | BB22: 0
A23: Belgium | B23: 0.05 | C23: 0.1 | D23: 0.02 | I23: Minimum | J23: 0.85 | P23: Svend Erik | Q23: 0 | R23: 0.1 | S23: 0 | T23: 0 | U23: 0 | V23: 0 | W23: 0 | X23: =SUM(Q23:W23) -> 0.1 | Z23: Svend Erik | AA23: 0.01 | AB23: 0.1 | AC23: 0.025 | AD23: 0.02 | AE23: 0.01 | AF23: 0.01 | AG23: 0.01 | AH23: =SUM(AA23:AG23) -> 0.185 | AL23: Standard 500 | AM23: 0.21 | AN23: 0.21 | AO23: 0.26 | AP23: 0.3 | AQ23: 24 | AR23: 16 | AS23: 24 | AT23: 40 | AU23: =SUM(AQ23:AT23) -> 104 | AV23: 0 | AW23: 1 | AY23: 0 | AZ23: 1 | BA23: 0 | BB23: 0
A24: Belize | B24: 0.05 | C24: 0.1 | D24: 0.02 | I24: Standard | J24: 0.7 | AL24: Standard 1000 | AM24: 0.21 | AN24: 0.21 | AO24: 0.26 | AP24: 0.3 | AQ24: 24 | AR24: 16 | AS24: 24 | AT24: 40 | AU24: =SUM(AQ24:AT24) -> 104 | AV24: 0 | AW24: 1 | AY24: 0 | AZ24: 1 | BA24: 0 | BB24: 0
A25: Benin | B25: 0.05 | C25: 0.1 | D25: 0.02 | I25: Extra | J25: 0.55 | P25: -- Tier 3 -- | Z25: -- Tier 3 -- | AL25: Vacuum 500 | AM25: 0.29 | AN25: 0.26 | AO25: 0.4 | AP25: 0.3 | AQ25: 24 | AR25: 16 | AS25: 24 | AT25: 40 | AU25: =SUM(AQ25:AT25) -> 104 | AV25: 0 | AX25: 1 | AY25: 1 | AZ25: 1 | BA25: 0 | BB25: 0
A26: Bhutan | B26: 0.05 | C26: 0.1 | D26: 0.02 | I26: Extra++ | J26: 0.4 | P26: Scandinavia | Q26: 0.02 | R26: 0.05 | S26: 0.02 | T26: 0.02 | U26: 0.02 | V26: 0.03 | W26: 0 | X26: =SUM(Q26:W26) -> 0.16 | Z26: Scandinavia | AA26: 0.01 | AB26: 0.1 | AC26: 0.025 | AD26: 0.02 | AE26: 0.02 | AF26: 0.02 | AG26: 0.02 | AH26: =SUM(AA26:AG26) -> 0.215 | AL26: Vacuum 1000 | AM26: 0.29 | AN26: 0.26 | AO26: 0.4 | AP26: 0.3 | AQ26: 24 | AR26: 16 | AS26: 24 | AT26: 40 | AU26: =SUM(AQ26:AT26) -> 104 | AV26: 0 | AX26: 1 | AY26: 1 | AZ26: 1 | BA26: 0 | BB26: 0
A27: Bolivia | B27: 0.05 | C27: 0.1 | D27: 0.02 | I27: Spare parts | J27: 0.2 | P27: Middle East | Q27: 0.02 | R27: 0.05 | S27: 0.02 | T27: 0.02 | U27: 0.02 | V27: 0.03 | W27: 0 | X27: =SUM(Q27:W27) -> 0.16 | Z27: Middle East | AA27: 0.01 | AB27: 0.1 | AC27: 0.05 | AD27: 0.02 | AE27: 0.02 | AF27: 0.02 | AG27: 0.02 | AH27: =SUM(AA27:AG27) -> 0.24 | AL27: Vacuum 3000 | AM27: 0.3 | AN27: 0.3 | AO27: 0.4 | AP27: 0.3 | AQ27: 80 | AR27: 40 | AS27: 40 | AT27: 60 | AU27: =SUM(AQ27:AT27) -> 220 | AV27: 0 | AX27: 1 | AY27: 1 | AZ27: 2 | BA27: 0 | BB27: 0
A28: Bosnia and Herzegovina | B28: 0.05 | C28: 0.1 | D28: 0.02 | P28: North America | Q28: 0.02 | R28: 0.05 | S28: 0.02 | T28: 0.02 | U28: 0.02 | V28: 0.03 | W28: 0 | X28: =SUM(Q28:W28) -> 0.16 | Z28: North America | AA28: 0.01 | AB28: 0.1 | AC28: 0.025 | AD28: 0.02 | AE28: 0.05 | AF28: 0.05 | AG28: 0.02 | AH28: =SUM(AA28:AG28) -> 0.275 | AL28: Process 500 | AM28: 0.26 | AN28: 0.26 | AO28: 0.35 | AP28: 0.3 | AQ28: 80 | AR28: 24 | AS28: 40 | AT28: 80 | AU28: =SUM(AQ28:AT28) -> 224 | AV28: 0 | AX28: 1 | AY28: 1 | AZ28: 2 | BA28: 0 | BB28: 0
A29: Botswana | B29: 0.05 | C29: 0.1 | D29: 0.02 | P29: Africa | Q29: 0.02 | R29: 0.05 | S29: 0.02 | T29: 0.02 | U29: 0.02 | V29: 0.03 | W29: 0 | X29: =SUM(Q29:W29) -> 0.16 | Z29: Africa | AA29: 0.01 | AB29: 0.1 | AC29: 0.025 | AD29: 0.02 | AE29: 0.02 | AF29: 0.02 | AG29: 0.02 | AH29: =SUM(AA29:AG29) -> 0.215 | AL29: Process 1000 | AM29: 0.3 | AN29: 0.26 | AO29: 0.35 | AP29: 0.3 | AQ29: 80 | AR29: 24 | AS29: 40 | AT29: 80 | AU29: =SUM(AQ29:AT29) -> 224 | AV29: 0 | AX29: 1 | AY29: 1 | AZ29: 2 | BA29: 0 | BB29: 0
A30: Brazil | B30: 0.05 | C30: 0.1 | D30: 0.02 | I30: Contingency | J30: 0.05 | P30: Germany | Q30: 0.02 | R30: 0.05 | S30: 0.02 | T30: 0.02 | U30: 0.02 | V30: 0.03 | W30: 0 | X30: =SUM(Q30:W30) -> 0.16 | Z30: Germany | AA30: 0.01 | AB30: 0.1 | AC30: 0.025 | AD30: 0.02 | AE30: 0.02 | AF30: 0.02 | AG30: 0.02 | AH30: =SUM(AA30:AG30) -> 0.215 | AL30: Process 3000 | AM30: 0.26 | AN30: 0.26 | AO30: 0.35 | AP30: 0.3 | AQ30: 160 | AR30: 40 | AS30: 40 | AT30: 80 | AU30: =SUM(AQ30:AT30) -> 320 | AV30: 0 | AX30: 1 | AY30: 1 | AZ30: 2 | BA30: 0 | BB30: 0
A31: Brunei | B31: 0.05 | C31: 0.1 | D31: 0.02 | I31: Cost savings markup | J31: 0.05 | AL31: EU Documentation | AQ31: 0 | AR31: 0 | AS31: 40 | AT31: 0 | AU31: =SUM(AQ31:AT31) -> 40 | AV31: 0 | AX31: 0 | AY31: 0 | AZ31: 0 | BA31: 0 | BB31: 0
A32: Bulgaria | B32: 0.05 | C32: 0.1 | D32: 0.02 | I32: Financial cost markup | J32: 0.01 | P32: -- Tier 4 -- | Z32: -- Tier 4 -- | AL32: Coxial | AM32: 0.25 | AN32: 0.25 | AO32: 0.35 | AP32: 0.3 | AQ32: 40 | AR32: 20 | AS32: 16 | AT32: 16 | AU32: =SUM(AQ32:AT32) -> 92 | AV32: 0 | AX32: 0.5 | AY32: 0.5 | AZ32: 0.5 | BA32: 0 | BB32: 0
A33: Burkina Faso | B33: 0.05 | C33: 0.1 | D33: 0.02 | I33: Warranty cost | J33: 0.02 | P33: JBT | Q33: 0.01 | R33: 0 | S33: 0.02 | T33: 0.02 | U33: 0.02 | V33: 0.02 | W33: 0 | X33: =SUM(Q33:W33) -> 0.09 | Z33: JBT | AA33: 0.01 | AB33: 0 | AC33: 0.03 | AD33: 0.02 | AE33: 0.02 | AF33: 0.02 | AG33: 0.02 | AH33: =SUM(AA33:AG33) -> 0.12 | AL33: Steam Injection nozzles | AM33: As mixer | AQ33: 40 | AR33: 5 | AS33: 5 | AT33: 5 | AU33: =SUM(AQ33:AT33) -> 55 | AV33: 0 | AX33: 0 | AY33: 0 | AZ33: 0 | BA33: 0 | BB33: 0
A34: Burundi | B34: 0.05 | C34: 0.1 | D34: 0.02 | P34: Krones | Q34: 0.01 | R34: 0 | S34: 0.01 | T34: 0.01 | U34: 0.01 | V34: 0.01 | W34: 0 | X34: =SUM(Q34:W34) -> 0.05 | Z34: Krones | AA34: 0.01 | AB34: 0 | AC34: 0.01 | AD34: 0.01 | AE34: 0.01 | AF34: 0.01 | AG34: 0.02 | AH34: =SUM(AA34:AG34) -> 0.07 | AL34: Culinary steam unit | AQ34: 40 | AR34: 5 | AS34: 5 | AT34: 5 | AU34: =SUM(AQ34:AT34) -> 55 | AX34: 0.25 | AY34: 0.25 | AZ34: 0.25 | BA34: 0 | BB34: 0
A35: Cabo Verde | B35: 0.05 | C35: 0.1 | D35: 0.02 | I35: Vacuum pummp | J35: No | P35: Dterm | Q35: 0.01 | R35: 0 | S35: 0.02 | T35: 0.02 | U35: 0.02 | V35: 0.02 | W35: 0 | X35: =SUM(Q35:W35) -> 0.09 | Z35: Dterm | AA35: 0.01 | AB35: 0 | AC35: 0.03 | AD35: 0.02 | AE35: 0.02 | AF35: 0.02 | AG35: 0.02 | AH35: =SUM(AA35:AG35) -> 0.12 | AL35: Control Panel & VSD, 11 kW | AM35: 0.15 | AN35: 0.15 | AO35: 0.15 | AP35: 0.3 | AQ35: 1 | AR35: 1 | AS35: 2 | AT35: 2 | AU35: =SUM(AQ35:AT35) -> 6 | AV35: 0 | AX35: 0 | AY35: 0 | AZ35: 0 | BA35: 0 | BB35: 0
